[2015-07-27 17:21:23 +0000] [2493] [ERROR] Exception in worker process:
Traceback (most recent call last):
  File "/home/ian/miniconda3/envs/py2.7/lib/python2.7/site-packages/gunicorn/arbiter.py", line 507, in spawn_worker
    worker.init_process()
  File "/home/ian/miniconda3/envs/py2.7/lib/python2.7/site-packages/gunicorn/workers/base.py", line 118, in init_process
    self.wsgi = self.app.wsgi()
  File "/home/ian/miniconda3/envs/py2.7/lib/python2.7/site-packages/gunicorn/app/base.py", line 67, in wsgi
    self.callable = self.load()
  File "/home/ian/miniconda3/envs/py2.7/lib/python2.7/site-packages/psiturk/experiment_server.py", line 49, in load
    return util.import_app("psiturk.experiment:app")
  File "/home/ian/miniconda3/envs/py2.7/lib/python2.7/site-packages/gunicorn/util.py", line 355, in import_app
    __import__(module)
  File "/home/ian/miniconda3/envs/py2.7/lib/python2.7/site-packages/psiturk/experiment.py", line 85, in <module>
    init_db()
  File "/home/ian/miniconda3/envs/py2.7/lib/python2.7/site-packages/psiturk/db.py", line 23, in init_db
    Base.metadata.create_all(bind=engine)
  File "/home/ian/miniconda3/envs/py2.7/lib/python2.7/site-packages/sqlalchemy/sql/schema.py", line 3622, in create_all
    tables=tables)
  File "/home/ian/miniconda3/envs/py2.7/lib/python2.7/site-packages/sqlalchemy/engine/base.py", line 1854, in _run_visitor
    conn._run_visitor(visitorcallable, element, **kwargs)
  File "/home/ian/miniconda3/envs/py2.7/lib/python2.7/site-packages/sqlalchemy/engine/base.py", line 1481, in _run_visitor
    **kwargs).traverse_single(element)
  File "/home/ian/miniconda3/envs/py2.7/lib/python2.7/site-packages/sqlalchemy/sql/visitors.py", line 121, in traverse_single
    return meth(obj, **kw)
  File "/home/ian/miniconda3/envs/py2.7/lib/python2.7/site-packages/sqlalchemy/sql/ddl.py", line 730, in visit_metadata
    _is_metadata_operation=True)
  File "/home/ian/miniconda3/envs/py2.7/lib/python2.7/site-packages/sqlalchemy/sql/visitors.py", line 121, in traverse_single
    return meth(obj, **kw)
  File "/home/ian/miniconda3/envs/py2.7/lib/python2.7/site-packages/sqlalchemy/sql/ddl.py", line 764, in visit_table
    include_foreign_key_constraints=include_foreign_key_constraints
  File "/home/ian/miniconda3/envs/py2.7/lib/python2.7/site-packages/sqlalchemy/engine/base.py", line 914, in execute
    return meth(self, multiparams, params)
  File "/home/ian/miniconda3/envs/py2.7/lib/python2.7/site-packages/sqlalchemy/sql/ddl.py", line 68, in _execute_on_connection
    return connection._execute_ddl(self, multiparams, params)
  File "/home/ian/miniconda3/envs/py2.7/lib/python2.7/site-packages/sqlalchemy/engine/base.py", line 968, in _execute_ddl
    compiled
  File "/home/ian/miniconda3/envs/py2.7/lib/python2.7/site-packages/sqlalchemy/engine/base.py", line 1146, in _execute_context
    context)
  File "/home/ian/miniconda3/envs/py2.7/lib/python2.7/site-packages/sqlalchemy/engine/base.py", line 1341, in _handle_dbapi_exception
    exc_info
  File "/home/ian/miniconda3/envs/py2.7/lib/python2.7/site-packages/sqlalchemy/util/compat.py", line 199, in raise_from_cause
    reraise(type(exception), exception, tb=exc_tb)
  File "/home/ian/miniconda3/envs/py2.7/lib/python2.7/site-packages/sqlalchemy/engine/base.py", line 1139, in _execute_context
    context)
  File "/home/ian/miniconda3/envs/py2.7/lib/python2.7/site-packages/sqlalchemy/engine/default.py", line 450, in do_execute
    cursor.execute(statement, parameters)
  File "/home/ian/miniconda3/envs/py2.7/lib/python2.7/site-packages/MySQLdb/cursors.py", line 205, in execute
    self.errorhandler(self, exc, value)
  File "/home/ian/miniconda3/envs/py2.7/lib/python2.7/site-packages/MySQLdb/connections.py", line 36, in defaulterrorhandler
    raise errorclass, errorvalue
OperationalError: (_mysql_exceptions.OperationalError) (1142, "CREATE command denied to user 'gpoldrackla_ro'@'sr15-e51dbb276a.stanford.edu' for table 'ControlOntology'") [SQL: u'\nCREATE TABLE `ControlOntology` (\n\tuniqueid VARCHAR(128) NOT NULL, \n\tassignmentid VARCHAR(128) NOT NULL, \n\tworkerid VARCHAR(128) NOT NULL, \n\thitid VARCHAR(128) NOT NULL, \n\tipaddress VARCHAR(128), \n\tbrowser VARCHAR(128), \n\tplatform VARCHAR(128), \n\tlanguage VARCHAR(128), \n\tcond INTEGER, \n\tcounterbalance INTEGER, \n\tcodeversion VARCHAR(128), \n\tbeginhit DATETIME, \n\tbeginexp DATETIME, \n\tendhit DATETIME, \n\tbonus FLOAT, \n\tstatus INTEGER, \n\tdatastring TEXT(4294967295), \n\tPRIMARY KEY (uniqueid)\n)\n\n']
Traceback (most recent call last):
  File "/home/ian/miniconda3/envs/py2.7/lib/python2.7/site-packages/gunicorn/arbiter.py", line 507, in spawn_worker
    worker.init_process()
  File "/home/ian/miniconda3/envs/py2.7/lib/python2.7/site-packages/gunicorn/workers/base.py", line 118, in init_process
    self.wsgi = self.app.wsgi()
  File "/home/ian/miniconda3/envs/py2.7/lib/python2.7/site-packages/gunicorn/app/base.py", line 67, in wsgi
    self.callable = self.load()
  File "/home/ian/miniconda3/envs/py2.7/lib/python2.7/site-packages/psiturk/experiment_server.py", line 49, in load
    return util.import_app("psiturk.experiment:app")
  File "/home/ian/miniconda3/envs/py2.7/lib/python2.7/site-packages/gunicorn/util.py", line 355, in import_app
    __import__(module)
  File "/home/ian/miniconda3/envs/py2.7/lib/python2.7/site-packages/psiturk/experiment.py", line 85, in <module>
    init_db()
  File "/home/ian/miniconda3/envs/py2.7/lib/python2.7/site-packages/psiturk/db.py", line 23, in init_db
    Base.metadata.create_all(bind=engine)
  File "/home/ian/miniconda3/envs/py2.7/lib/python2.7/site-packages/sqlalchemy/sql/schema.py", line 3622, in create_all
    tables=tables)
  File "/home/ian/miniconda3/envs/py2.7/lib/python2.7/site-packages/sqlalchemy/engine/base.py", line 1854, in _run_visitor
    conn._run_visitor(visitorcallable, element, **kwargs)
  File "/home/ian/miniconda3/envs/py2.7/lib/python2.7/site-packages/sqlalchemy/engine/base.py", line 1481, in _run_visitor
    **kwargs).traverse_single(element)
  File "/home/ian/miniconda3/envs/py2.7/lib/python2.7/site-packages/sqlalchemy/sql/visitors.py", line 121, in traverse_single
    return meth(obj, **kw)
  File "/home/ian/miniconda3/envs/py2.7/lib/python2.7/site-packages/sqlalchemy/sql/ddl.py", line 730, in visit_metadata
    _is_metadata_operation=True)
  File "/home/ian/miniconda3/envs/py2.7/lib/python2.7/site-packages/sqlalchemy/sql/visitors.py", line 121, in traverse_single
    return meth(obj, **kw)
  File "/home/ian/miniconda3/envs/py2.7/lib/python2.7/site-packages/sqlalchemy/sql/ddl.py", line 764, in visit_table
    include_foreign_key_constraints=include_foreign_key_constraints
  File "/home/ian/miniconda3/envs/py2.7/lib/python2.7/site-packages/sqlalchemy/engine/base.py", line 914, in execute
    return meth(self, multiparams, params)
  File "/home/ian/miniconda3/envs/py2.7/lib/python2.7/site-packages/sqlalchemy/sql/ddl.py", line 68, in _execute_on_connection
    return connection._execute_ddl(self, multiparams, params)
  File "/home/ian/miniconda3/envs/py2.7/lib/python2.7/site-packages/sqlalchemy/engine/base.py", line 968, in _execute_ddl
    compiled
  File "/home/ian/miniconda3/envs/py2.7/lib/python2.7/site-packages/sqlalchemy/engine/base.py", line 1146, in _execute_context
    context)
  File "/home/ian/miniconda3/envs/py2.7/lib/python2.7/site-packages/sqlalchemy/engine/base.py", line 1341, in _handle_dbapi_exception
    exc_info
  File "/home/ian/miniconda3/envs/py2.7/lib/python2.7/site-packages/sqlalchemy/util/compat.py", line 199, in raise_from_cause
    reraise(type(exception), exception, tb=exc_tb)
  File "/home/ian/miniconda3/envs/py2.7/lib/python2.7/site-packages/sqlalchemy/engine/base.py", line 1139, in _execute_context
    context)
  File "/home/ian/miniconda3/envs/py2.7/lib/python2.7/site-packages/sqlalchemy/engine/default.py", line 450, in do_execute
    cursor.execute(statement, parameters)
  File "/home/ian/miniconda3/envs/py2.7/lib/python2.7/site-packages/MySQLdb/cursors.py", line 205, in execute
    self.errorhandler(self, exc, value)
  File "/home/ian/miniconda3/envs/py2.7/lib/python2.7/site-packages/MySQLdb/connections.py", line 36, in defaulterrorhandler
    raise errorclass, errorvalue
OperationalError: (_mysql_exceptions.OperationalError) (1142, "CREATE command denied to user 'gpoldrackla_ro'@'sr15-e51dbb276a.stanford.edu' for table 'ControlOntology'") [SQL: u'\nCREATE TABLE `ControlOntology` (\n\tuniqueid VARCHAR(128) NOT NULL, \n\tassignmentid VARCHAR(128) NOT NULL, \n\tworkerid VARCHAR(128) NOT NULL, \n\thitid VARCHAR(128) NOT NULL, \n\tipaddress VARCHAR(128), \n\tbrowser VARCHAR(128), \n\tplatform VARCHAR(128), \n\tlanguage VARCHAR(128), \n\tcond INTEGER, \n\tcounterbalance INTEGER, \n\tcodeversion VARCHAR(128), \n\tbeginhit DATETIME, \n\tbeginexp DATETIME, \n\tendhit DATETIME, \n\tbonus FLOAT, \n\tstatus INTEGER, \n\tdatastring TEXT(4294967295), \n\tPRIMARY KEY (uniqueid)\n)\n\n']
[2015-07-27 17:21:23 +0000] [2494] [ERROR] Exception in worker process:
Traceback (most recent call last):
  File "/home/ian/miniconda3/envs/py2.7/lib/python2.7/site-packages/gunicorn/arbiter.py", line 507, in spawn_worker
    worker.init_process()
  File "/home/ian/miniconda3/envs/py2.7/lib/python2.7/site-packages/gunicorn/workers/base.py", line 118, in init_process
    self.wsgi = self.app.wsgi()
  File "/home/ian/miniconda3/envs/py2.7/lib/python2.7/site-packages/gunicorn/app/base.py", line 67, in wsgi
    self.callable = self.load()
  File "/home/ian/miniconda3/envs/py2.7/lib/python2.7/site-packages/psiturk/experiment_server.py", line 49, in load
    return util.import_app("psiturk.experiment:app")
  File "/home/ian/miniconda3/envs/py2.7/lib/python2.7/site-packages/gunicorn/util.py", line 355, in import_app
    __import__(module)
  File "/home/ian/miniconda3/envs/py2.7/lib/python2.7/site-packages/psiturk/experiment.py", line 85, in <module>
    init_db()
  File "/home/ian/miniconda3/envs/py2.7/lib/python2.7/site-packages/psiturk/db.py", line 23, in init_db
    Base.metadata.create_all(bind=engine)
  File "/home/ian/miniconda3/envs/py2.7/lib/python2.7/site-packages/sqlalchemy/sql/schema.py", line 3622, in create_all
    tables=tables)
  File "/home/ian/miniconda3/envs/py2.7/lib/python2.7/site-packages/sqlalchemy/engine/base.py", line 1854, in _run_visitor
    conn._run_visitor(visitorcallable, element, **kwargs)
  File "/home/ian/miniconda3/envs/py2.7/lib/python2.7/site-packages/sqlalchemy/engine/base.py", line 1481, in _run_visitor
    **kwargs).traverse_single(element)
  File "/home/ian/miniconda3/envs/py2.7/lib/python2.7/site-packages/sqlalchemy/sql/visitors.py", line 121, in traverse_single
    return meth(obj, **kw)
  File "/home/ian/miniconda3/envs/py2.7/lib/python2.7/site-packages/sqlalchemy/sql/ddl.py", line 730, in visit_metadata
    _is_metadata_operation=True)
  File "/home/ian/miniconda3/envs/py2.7/lib/python2.7/site-packages/sqlalchemy/sql/visitors.py", line 121, in traverse_single
    return meth(obj, **kw)
  File "/home/ian/miniconda3/envs/py2.7/lib/python2.7/site-packages/sqlalchemy/sql/ddl.py", line 764, in visit_table
    include_foreign_key_constraints=include_foreign_key_constraints
  File "/home/ian/miniconda3/envs/py2.7/lib/python2.7/site-packages/sqlalchemy/engine/base.py", line 914, in execute
    return meth(self, multiparams, params)
  File "/home/ian/miniconda3/envs/py2.7/lib/python2.7/site-packages/sqlalchemy/sql/ddl.py", line 68, in _execute_on_connection
    return connection._execute_ddl(self, multiparams, params)
  File "/home/ian/miniconda3/envs/py2.7/lib/python2.7/site-packages/sqlalchemy/engine/base.py", line 968, in _execute_ddl
    compiled
  File "/home/ian/miniconda3/envs/py2.7/lib/python2.7/site-packages/sqlalchemy/engine/base.py", line 1146, in _execute_context
    context)
  File "/home/ian/miniconda3/envs/py2.7/lib/python2.7/site-packages/sqlalchemy/engine/base.py", line 1341, in _handle_dbapi_exception
    exc_info
  File "/home/ian/miniconda3/envs/py2.7/lib/python2.7/site-packages/sqlalchemy/util/compat.py", line 199, in raise_from_cause
    reraise(type(exception), exception, tb=exc_tb)
  File "/home/ian/miniconda3/envs/py2.7/lib/python2.7/site-packages/sqlalchemy/engine/base.py", line 1139, in _execute_context
    context)
  File "/home/ian/miniconda3/envs/py2.7/lib/python2.7/site-packages/sqlalchemy/engine/default.py", line 450, in do_execute
    cursor.execute(statement, parameters)
  File "/home/ian/miniconda3/envs/py2.7/lib/python2.7/site-packages/MySQLdb/cursors.py", line 205, in execute
    self.errorhandler(self, exc, value)
  File "/home/ian/miniconda3/envs/py2.7/lib/python2.7/site-packages/MySQLdb/connections.py", line 36, in defaulterrorhandler
    raise errorclass, errorvalue
OperationalError: (_mysql_exceptions.OperationalError) (1142, "CREATE command denied to user 'gpoldrackla_ro'@'sr15-e51dbb276a.stanford.edu' for table 'ControlOntology'") [SQL: u'\nCREATE TABLE `ControlOntology` (\n\tuniqueid VARCHAR(128) NOT NULL, \n\tassignmentid VARCHAR(128) NOT NULL, \n\tworkerid VARCHAR(128) NOT NULL, \n\thitid VARCHAR(128) NOT NULL, \n\tipaddress VARCHAR(128), \n\tbrowser VARCHAR(128), \n\tplatform VARCHAR(128), \n\tlanguage VARCHAR(128), \n\tcond INTEGER, \n\tcounterbalance INTEGER, \n\tcodeversion VARCHAR(128), \n\tbeginhit DATETIME, \n\tbeginexp DATETIME, \n\tendhit DATETIME, \n\tbonus FLOAT, \n\tstatus INTEGER, \n\tdatastring TEXT(4294967295), \n\tPRIMARY KEY (uniqueid)\n)\n\n']
Traceback (most recent call last):
  File "/home/ian/miniconda3/envs/py2.7/lib/python2.7/site-packages/gunicorn/arbiter.py", line 507, in spawn_worker
    worker.init_process()
  File "/home/ian/miniconda3/envs/py2.7/lib/python2.7/site-packages/gunicorn/workers/base.py", line 118, in init_process
    self.wsgi = self.app.wsgi()
  File "/home/ian/miniconda3/envs/py2.7/lib/python2.7/site-packages/gunicorn/app/base.py", line 67, in wsgi
    self.callable = self.load()
  File "/home/ian/miniconda3/envs/py2.7/lib/python2.7/site-packages/psiturk/experiment_server.py", line 49, in load
    return util.import_app("psiturk.experiment:app")
  File "/home/ian/miniconda3/envs/py2.7/lib/python2.7/site-packages/gunicorn/util.py", line 355, in import_app
    __import__(module)
  File "/home/ian/miniconda3/envs/py2.7/lib/python2.7/site-packages/psiturk/experiment.py", line 85, in <module>
    init_db()
  File "/home/ian/miniconda3/envs/py2.7/lib/python2.7/site-packages/psiturk/db.py", line 23, in init_db
    Base.metadata.create_all(bind=engine)
  File "/home/ian/miniconda3/envs/py2.7/lib/python2.7/site-packages/sqlalchemy/sql/schema.py", line 3622, in create_all
    tables=tables)
  File "/home/ian/miniconda3/envs/py2.7/lib/python2.7/site-packages/sqlalchemy/engine/base.py", line 1854, in _run_visitor
    conn._run_visitor(visitorcallable, element, **kwargs)
  File "/home/ian/miniconda3/envs/py2.7/lib/python2.7/site-packages/sqlalchemy/engine/base.py", line 1481, in _run_visitor
    **kwargs).traverse_single(element)
  File "/home/ian/miniconda3/envs/py2.7/lib/python2.7/site-packages/sqlalchemy/sql/visitors.py", line 121, in traverse_single
    return meth(obj, **kw)
  File "/home/ian/miniconda3/envs/py2.7/lib/python2.7/site-packages/sqlalchemy/sql/ddl.py", line 730, in visit_metadata
    _is_metadata_operation=True)
  File "/home/ian/miniconda3/envs/py2.7/lib/python2.7/site-packages/sqlalchemy/sql/visitors.py", line 121, in traverse_single
    return meth(obj, **kw)
  File "/home/ian/miniconda3/envs/py2.7/lib/python2.7/site-packages/sqlalchemy/sql/ddl.py", line 764, in visit_table
    include_foreign_key_constraints=include_foreign_key_constraints
  File "/home/ian/miniconda3/envs/py2.7/lib/python2.7/site-packages/sqlalchemy/engine/base.py", line 914, in execute
    return meth(self, multiparams, params)
  File "/home/ian/miniconda3/envs/py2.7/lib/python2.7/site-packages/sqlalchemy/sql/ddl.py", line 68, in _execute_on_connection
    return connection._execute_ddl(self, multiparams, params)
  File "/home/ian/miniconda3/envs/py2.7/lib/python2.7/site-packages/sqlalchemy/engine/base.py", line 968, in _execute_ddl
    compiled
  File "/home/ian/miniconda3/envs/py2.7/lib/python2.7/site-packages/sqlalchemy/engine/base.py", line 1146, in _execute_context
    context)
  File "/home/ian/miniconda3/envs/py2.7/lib/python2.7/site-packages/sqlalchemy/engine/base.py", line 1341, in _handle_dbapi_exception
    exc_info
  File "/home/ian/miniconda3/envs/py2.7/lib/python2.7/site-packages/sqlalchemy/util/compat.py", line 199, in raise_from_cause
    reraise(type(exception), exception, tb=exc_tb)
  File "/home/ian/miniconda3/envs/py2.7/lib/python2.7/site-packages/sqlalchemy/engine/base.py", line 1139, in _execute_context
    context)
  File "/home/ian/miniconda3/envs/py2.7/lib/python2.7/site-packages/sqlalchemy/engine/default.py", line 450, in do_execute
    cursor.execute(statement, parameters)
  File "/home/ian/miniconda3/envs/py2.7/lib/python2.7/site-packages/MySQLdb/cursors.py", line 205, in execute
    self.errorhandler(self, exc, value)
  File "/home/ian/miniconda3/envs/py2.7/lib/python2.7/site-packages/MySQLdb/connections.py", line 36, in defaulterrorhandler
    raise errorclass, errorvalue
OperationalError: (_mysql_exceptions.OperationalError) (1142, "CREATE command denied to user 'gpoldrackla_ro'@'sr15-e51dbb276a.stanford.edu' for table 'ControlOntology'") [SQL: u'\nCREATE TABLE `ControlOntology` (\n\tuniqueid VARCHAR(128) NOT NULL, \n\tassignmentid VARCHAR(128) NOT NULL, \n\tworkerid VARCHAR(128) NOT NULL, \n\thitid VARCHAR(128) NOT NULL, \n\tipaddress VARCHAR(128), \n\tbrowser VARCHAR(128), \n\tplatform VARCHAR(128), \n\tlanguage VARCHAR(128), \n\tcond INTEGER, \n\tcounterbalance INTEGER, \n\tcodeversion VARCHAR(128), \n\tbeginhit DATETIME, \n\tbeginexp DATETIME, \n\tendhit DATETIME, \n\tbonus FLOAT, \n\tstatus INTEGER, \n\tdatastring TEXT(4294967295), \n\tPRIMARY KEY (uniqueid)\n)\n\n']
[2015-07-27 17:21:23 +0000] [2495] [ERROR] Exception in worker process:
Traceback (most recent call last):
  File "/home/ian/miniconda3/envs/py2.7/lib/python2.7/site-packages/gunicorn/arbiter.py", line 507, in spawn_worker
    worker.init_process()
  File "/home/ian/miniconda3/envs/py2.7/lib/python2.7/site-packages/gunicorn/workers/base.py", line 118, in init_process
    self.wsgi = self.app.wsgi()
  File "/home/ian/miniconda3/envs/py2.7/lib/python2.7/site-packages/gunicorn/app/base.py", line 67, in wsgi
    self.callable = self.load()
  File "/home/ian/miniconda3/envs/py2.7/lib/python2.7/site-packages/psiturk/experiment_server.py", line 49, in load
    return util.import_app("psiturk.experiment:app")
  File "/home/ian/miniconda3/envs/py2.7/lib/python2.7/site-packages/gunicorn/util.py", line 355, in import_app
    __import__(module)
  File "/home/ian/miniconda3/envs/py2.7/lib/python2.7/site-packages/psiturk/experiment.py", line 85, in <module>
    init_db()
  File "/home/ian/miniconda3/envs/py2.7/lib/python2.7/site-packages/psiturk/db.py", line 23, in init_db
    Base.metadata.create_all(bind=engine)
  File "/home/ian/miniconda3/envs/py2.7/lib/python2.7/site-packages/sqlalchemy/sql/schema.py", line 3622, in create_all
    tables=tables)
  File "/home/ian/miniconda3/envs/py2.7/lib/python2.7/site-packages/sqlalchemy/engine/base.py", line 1854, in _run_visitor
    conn._run_visitor(visitorcallable, element, **kwargs)
  File "/home/ian/miniconda3/envs/py2.7/lib/python2.7/site-packages/sqlalchemy/engine/base.py", line 1481, in _run_visitor
    **kwargs).traverse_single(element)
  File "/home/ian/miniconda3/envs/py2.7/lib/python2.7/site-packages/sqlalchemy/sql/visitors.py", line 121, in traverse_single
    return meth(obj, **kw)
  File "/home/ian/miniconda3/envs/py2.7/lib/python2.7/site-packages/sqlalchemy/sql/ddl.py", line 730, in visit_metadata
    _is_metadata_operation=True)
  File "/home/ian/miniconda3/envs/py2.7/lib/python2.7/site-packages/sqlalchemy/sql/visitors.py", line 121, in traverse_single
    return meth(obj, **kw)
  File "/home/ian/miniconda3/envs/py2.7/lib/python2.7/site-packages/sqlalchemy/sql/ddl.py", line 764, in visit_table
    include_foreign_key_constraints=include_foreign_key_constraints
  File "/home/ian/miniconda3/envs/py2.7/lib/python2.7/site-packages/sqlalchemy/engine/base.py", line 914, in execute
    return meth(self, multiparams, params)
  File "/home/ian/miniconda3/envs/py2.7/lib/python2.7/site-packages/sqlalchemy/sql/ddl.py", line 68, in _execute_on_connection
    return connection._execute_ddl(self, multiparams, params)
  File "/home/ian/miniconda3/envs/py2.7/lib/python2.7/site-packages/sqlalchemy/engine/base.py", line 968, in _execute_ddl
    compiled
  File "/home/ian/miniconda3/envs/py2.7/lib/python2.7/site-packages/sqlalchemy/engine/base.py", line 1146, in _execute_context
    context)
  File "/home/ian/miniconda3/envs/py2.7/lib/python2.7/site-packages/sqlalchemy/engine/base.py", line 1341, in _handle_dbapi_exception
    exc_info
  File "/home/ian/miniconda3/envs/py2.7/lib/python2.7/site-packages/sqlalchemy/util/compat.py", line 199, in raise_from_cause
    reraise(type(exception), exception, tb=exc_tb)
  File "/home/ian/miniconda3/envs/py2.7/lib/python2.7/site-packages/sqlalchemy/engine/base.py", line 1139, in _execute_context
    context)
  File "/home/ian/miniconda3/envs/py2.7/lib/python2.7/site-packages/sqlalchemy/engine/default.py", line 450, in do_execute
    cursor.execute(statement, parameters)
  File "/home/ian/miniconda3/envs/py2.7/lib/python2.7/site-packages/MySQLdb/cursors.py", line 205, in execute
    self.errorhandler(self, exc, value)
  File "/home/ian/miniconda3/envs/py2.7/lib/python2.7/site-packages/MySQLdb/connections.py", line 36, in defaulterrorhandler
    raise errorclass, errorvalue
OperationalError: (_mysql_exceptions.OperationalError) (1142, "CREATE command denied to user 'gpoldrackla_ro'@'sr15-e51dbb276a.stanford.edu' for table 'ControlOntology'") [SQL: u'\nCREATE TABLE `ControlOntology` (\n\tuniqueid VARCHAR(128) NOT NULL, \n\tassignmentid VARCHAR(128) NOT NULL, \n\tworkerid VARCHAR(128) NOT NULL, \n\thitid VARCHAR(128) NOT NULL, \n\tipaddress VARCHAR(128), \n\tbrowser VARCHAR(128), \n\tplatform VARCHAR(128), \n\tlanguage VARCHAR(128), \n\tcond INTEGER, \n\tcounterbalance INTEGER, \n\tcodeversion VARCHAR(128), \n\tbeginhit DATETIME, \n\tbeginexp DATETIME, \n\tendhit DATETIME, \n\tbonus FLOAT, \n\tstatus INTEGER, \n\tdatastring TEXT(4294967295), \n\tPRIMARY KEY (uniqueid)\n)\n\n']
Traceback (most recent call last):
  File "/home/ian/miniconda3/envs/py2.7/lib/python2.7/site-packages/gunicorn/arbiter.py", line 507, in spawn_worker
    worker.init_process()
  File "/home/ian/miniconda3/envs/py2.7/lib/python2.7/site-packages/gunicorn/workers/base.py", line 118, in init_process
    self.wsgi = self.app.wsgi()
  File "/home/ian/miniconda3/envs/py2.7/lib/python2.7/site-packages/gunicorn/app/base.py", line 67, in wsgi
    self.callable = self.load()
  File "/home/ian/miniconda3/envs/py2.7/lib/python2.7/site-packages/psiturk/experiment_server.py", line 49, in load
    return util.import_app("psiturk.experiment:app")
  File "/home/ian/miniconda3/envs/py2.7/lib/python2.7/site-packages/gunicorn/util.py", line 355, in import_app
    __import__(module)
  File "/home/ian/miniconda3/envs/py2.7/lib/python2.7/site-packages/psiturk/experiment.py", line 85, in <module>
    init_db()
  File "/home/ian/miniconda3/envs/py2.7/lib/python2.7/site-packages/psiturk/db.py", line 23, in init_db
    Base.metadata.create_all(bind=engine)
  File "/home/ian/miniconda3/envs/py2.7/lib/python2.7/site-packages/sqlalchemy/sql/schema.py", line 3622, in create_all
    tables=tables)
  File "/home/ian/miniconda3/envs/py2.7/lib/python2.7/site-packages/sqlalchemy/engine/base.py", line 1854, in _run_visitor
    conn._run_visitor(visitorcallable, element, **kwargs)
  File "/home/ian/miniconda3/envs/py2.7/lib/python2.7/site-packages/sqlalchemy/engine/base.py", line 1481, in _run_visitor
    **kwargs).traverse_single(element)
  File "/home/ian/miniconda3/envs/py2.7/lib/python2.7/site-packages/sqlalchemy/sql/visitors.py", line 121, in traverse_single
    return meth(obj, **kw)
  File "/home/ian/miniconda3/envs/py2.7/lib/python2.7/site-packages/sqlalchemy/sql/ddl.py", line 730, in visit_metadata
    _is_metadata_operation=True)
  File "/home/ian/miniconda3/envs/py2.7/lib/python2.7/site-packages/sqlalchemy/sql/visitors.py", line 121, in traverse_single
    return meth(obj, **kw)
  File "/home/ian/miniconda3/envs/py2.7/lib/python2.7/site-packages/sqlalchemy/sql/ddl.py", line 764, in visit_table
    include_foreign_key_constraints=include_foreign_key_constraints
  File "/home/ian/miniconda3/envs/py2.7/lib/python2.7/site-packages/sqlalchemy/engine/base.py", line 914, in execute
    return meth(self, multiparams, params)
  File "/home/ian/miniconda3/envs/py2.7/lib/python2.7/site-packages/sqlalchemy/sql/ddl.py", line 68, in _execute_on_connection
    return connection._execute_ddl(self, multiparams, params)
  File "/home/ian/miniconda3/envs/py2.7/lib/python2.7/site-packages/sqlalchemy/engine/base.py", line 968, in _execute_ddl
    compiled
  File "/home/ian/miniconda3/envs/py2.7/lib/python2.7/site-packages/sqlalchemy/engine/base.py", line 1146, in _execute_context
    context)
  File "/home/ian/miniconda3/envs/py2.7/lib/python2.7/site-packages/sqlalchemy/engine/base.py", line 1341, in _handle_dbapi_exception
    exc_info
  File "/home/ian/miniconda3/envs/py2.7/lib/python2.7/site-packages/sqlalchemy/util/compat.py", line 199, in raise_from_cause
    reraise(type(exception), exception, tb=exc_tb)
  File "/home/ian/miniconda3/envs/py2.7/lib/python2.7/site-packages/sqlalchemy/engine/base.py", line 1139, in _execute_context
    context)
  File "/home/ian/miniconda3/envs/py2.7/lib/python2.7/site-packages/sqlalchemy/engine/default.py", line 450, in do_execute
    cursor.execute(statement, parameters)
  File "/home/ian/miniconda3/envs/py2.7/lib/python2.7/site-packages/MySQLdb/cursors.py", line 205, in execute
    self.errorhandler(self, exc, value)
  File "/home/ian/miniconda3/envs/py2.7/lib/python2.7/site-packages/MySQLdb/connections.py", line 36, in defaulterrorhandler
    raise errorclass, errorvalue
OperationalError: (_mysql_exceptions.OperationalError) (1142, "CREATE command denied to user 'gpoldrackla_ro'@'sr15-e51dbb276a.stanford.edu' for table 'ControlOntology'") [SQL: u'\nCREATE TABLE `ControlOntology` (\n\tuniqueid VARCHAR(128) NOT NULL, \n\tassignmentid VARCHAR(128) NOT NULL, \n\tworkerid VARCHAR(128) NOT NULL, \n\thitid VARCHAR(128) NOT NULL, \n\tipaddress VARCHAR(128), \n\tbrowser VARCHAR(128), \n\tplatform VARCHAR(128), \n\tlanguage VARCHAR(128), \n\tcond INTEGER, \n\tcounterbalance INTEGER, \n\tcodeversion VARCHAR(128), \n\tbeginhit DATETIME, \n\tbeginexp DATETIME, \n\tendhit DATETIME, \n\tbonus FLOAT, \n\tstatus INTEGER, \n\tdatastring TEXT(4294967295), \n\tPRIMARY KEY (uniqueid)\n)\n\n']
